Workbook
Name EarlyDays: Config!$B$4
Name WarnDays: Config!$B$5
Name DueDays: Config!$B$6
Name ReminderGapDays: Config!$B$7
Name RedAlert: Config!$B$8

Sheet Dashboard
B2: 💳 CARD OPERATIONS — CONTROL CENTRE | P2: =TEXT(TODAY(),"dddd, dd mmm yyyy")
B5: =IF(COUNTIFS('Card Register'!$H$2:$H$50,"Held",'Card Register'!$G$2:$G$50,">="&DueDays)>RedAlert,"⚠ "&COUNTIFS('Card Register'!$H$2:$H$50,"Held",'Card Register'!$G$2:$G$50,">="&DueDays)&" held cards are DUE FOR DESTRUCTION (limit "&RedAlert&"). Run the Destruction Register + final-notice reminders.","✓ Destruction backlog under control — "&COUNTIFS('Card Register'!$H$2:$H$50,"Held",'Card Register'!$G$2:$G$50,">="&DueDays)&" card(s) at/over 90 days.")
B7: THE CARD CYCLE
B8: ① RECORD | F8: =COUNTA(CardRegister[Card Number]) | I8: ② LIFECYCLE | M8: =COUNTIF('Card Register'!$H$2:$H$50,"Held*") | P8: ③ REMIND | T8: =COUNTIF(CardRegister[Needs Reminder],"Yes")
B10: Logged on arrival | I10: In branch, ageing | P10: Reminders due now
B12: KEY METRICS
B13: 🗂 TOTAL CARDS | E13: 🏦 IN BRANCH | H13: ✅ COLLECTED | K13: 🗑 DESTROYED | N13: ⛔ DUE FOR DESTRUCTION | Q13: ✉ NEEDS REMINDER
B14: =COUNTA(CardRegister[Card Number]) | E14: =COUNTIF('Card Register'!$H$2:$H$50,"Held*") | H14: =COUNTIF('Card Register'!$H$2:$H$50,"Issued*") | K14: =COUNTIF('Card Register'!$H$2:$H$50,"Destroyed*") | N14: =COUNTIFS('Card Register'!$H$2:$H$50,"Held",'Card Register'!$G$2:$G$50,">="&DueDays) | Q14: =COUNTIF(CardRegister[Needs Reminder],"Yes")
B18: PORTFOLIO STATUS | J18: AGEING DISTRIBUTION (days in branch)
B33: RECORDING TREND — cards logged per month | J33: BRANCH HEALTH (share by age band)
B46: OLDEST CARDS IN BRANCH — action queue (oldest first)
B47: Customer | G47: Card Number | J47: Days | L47: Band | N47: Reminders | P47: Last Contact
B48: =IFERROR(LET(h,FILTER(CardRegister[[Customer Name]:[Reminders Sent]],CardRegister[Status]="Held"),TAKE(SORT(CHOOSECOLS(h,1,2,6,11,15),3,-1),10)),"No cards are currently Held — nothing in the action queue.")
B58: Live workbook · ageing = TODAY()−Date Received · thresholds on Config · reminders & destruction handled by the register's VBA (SendCardEmails / GenerateDestructionRegister).

Sheet Config
A1: Card Lifecycle — Configuration
A3: Name | B3: Value | C3: Meaning
A4: EarlyDays | B4: 30 | C4: New band ceiling (0-29 days)
A5: WarnDays | B5: 60 | C5: Warning band starts (60 days)
A6: DueDays | B6: 90 | C6: Destruction due (90 days) — the rule
A7: ReminderGapDays | B7: 7 | C7: Min days between reminder emails (anti-spam)
A8: RedAlert | B8: 5 | C8: Banner fires when due-for-destruction exceeds this

Sheet Card Register
A1: Date | B1: Customer Name | C1: Card Number | D1: Card Type | E1: Phone Number | F1: Email Address | G1: Days in Branch | H1: Status | I1: Date Issued | J1: Last Contact | K1: Notes | L1: Age Band | M1: Lifecycle Stage | N1: Due for Destruction | O1: Days Overdue | P1: Reminders Sent | Q1: Needs Reminder
A2: 46024 | B2: Garet Ochieng | C2: 547743*2086 | E2: 0717071977 | G2: =IF($I2="",TODAY()-$A2,$I2-$A2) | H2: Destroyed | K2: Account closed | L2: =IF($G2>=DueDays,"Due",IF($G2>=WarnDays,"Warning",IF($G2>=EarlyDays,"Normal","New"))) | M2: =IFS($H2="Held","In Branch",$H2="Issued","Collected",$H2="Destroyed","Destroyed",TRUE,"Pending") | N2: =AND($H2="Held",$G2>=DueDays) | O2: =IF($N2,$G2-DueDays,"") | P2: =COUNTIF('Communication Log'!$C:$C,$C2) | Q2: =IF($H2<>"Held","No",IF(AND($G2>=EarlyDays,OR($J2="",TODAY()-$J2>=ReminderGapDays)),"Yes","No"))
A3: 46027 | B3: Margaret Wangui Njora | C3: 547743*9951 | E3: 0701609409 | F3: MARGARETNJORA6@GMAIL.COM | G3: =IF($I3="",TODAY()-$A3,$I3-$A3) | H3: Issued | I3: 46104 | K3: Thika | L3: =IF($G3>=DueDays,"Due",IF($G3>=WarnDays,"Warning",IF($G3>=EarlyDays,"Normal","New"))) | M3: =IFS($H3="Held","In Branch",$H3="Issued","Collected",$H3="Destroyed","Destroyed",TRUE,"Pending") | N3: =AND($H3="Held",$G3>=DueDays) | O3: =IF($N3,$G3-DueDays,"") | P3: =COUNTIF('Communication Log'!$C:$C,$C3) | Q3: =IF($H3<>"Held","No",IF(AND($G3>=EarlyDays,OR($J3="",TODAY()-$J3>=ReminderGapDays)),"Yes","No"))
A4: 46043 | B4: Salome Njoki Nyoro | C4: 547743*9984 | E4: 0722782686 | G4: =IF($I4="",TODAY()-$A4,$I4-$A4) | H4: Issued | I4: 46043 | L4: =IF($G4>=DueDays,"Due",IF($G4>=WarnDays,"Warning",IF($G4>=EarlyDays,"Normal","New"))) | M4: =IFS($H4="Held","In Branch",$H4="Issued","Collected",$H4="Destroyed","Destroyed",TRUE,"Pending") | N4: =AND($H4="Held",$G4>=DueDays) | O4: =IF($N4,$G4-DueDays,"") | P4: =COUNTIF('Communication Log'!$C:$C,$C4) | Q4: =IF($H4<>"Held","No",IF(AND($G4>=EarlyDays,OR($J4="",TODAY()-$J4>=ReminderGapDays)),"Yes","No"))
A5: 46044 | B5: Jeesha Panchal | C5: 555458*5087 | E5: N/A | G5: =IF($I5="",TODAY()-$A5,$I5-$A5) | H5: Issued | I5: 46044 | L5: =IF($G5>=DueDays,"Due",IF($G5>=WarnDays,"Warning",IF($G5>=EarlyDays,"Normal","New"))) | M5: =IFS($H5="Held","In Branch",$H5="Issued","Collected",$H5="Destroyed","Destroyed",TRUE,"Pending") | N5: =AND($H5="Held",$G5>=DueDays) | O5: =IF($N5,$G5-DueDays,"") | P5: =COUNTIF('Communication Log'!$C:$C,$C5) | Q5: =IF($H5<>"Held","No",IF(AND($G5>=EarlyDays,OR($J5="",TODAY()-$J5>=ReminderGapDays)),"Yes","No"))
A6: 46029 | B6: Stacy a Liposhe | C6: 547743*7765 | E6: 0792967765 | G6: =IF($I6="",TODAY()-$A6,$I6-$A6) | H6: Issued | I6: 46048 | L6: =IF($G6>=DueDays,"Due",IF($G6>=WarnDays,"Warning",IF($G6>=EarlyDays,"Normal","New"))) | M6: =IFS($H6="Held","In Branch",$H6="Issued","Collected",$H6="Destroyed","Destroyed",TRUE,"Pending") | N6: =AND($H6="Held",$G6>=DueDays) | O6: =IF($N6,$G6-DueDays,"") | P6: =COUNTIF('Communication Log'!$C:$C,$C6) | Q6: =IF($H6<>"Held","No",IF(AND($G6>=EarlyDays,OR($J6="",TODAY()-$J6>=ReminderGapDays)),"Yes","No"))
A7: 46049 | B7: Samuel Kinyeki | C7: 547743*5034 | E7: 0725254611 | F7: SAMUELKINYEKI@GMAIL.COM | G7: =IF($I7="",TODAY()-$A7,$I7-$A7) | H7: Issued | I7: 46049 | L7: =IF($G7>=DueDays,"Due",IF($G7>=WarnDays,"Warning",IF($G7>=EarlyDays,"Normal","New"))) | M7: =IFS($H7="Held","In Branch",$H7="Issued","Collected",$H7="Destroyed","Destroyed",TRUE,"Pending") | N7: =AND($H7="Held",$G7>=DueDays) | O7: =IF($N7,$G7-DueDays,"") | P7: =COUNTIF('Communication Log'!$C:$C,$C7) | Q7: =IF($H7<>"Held","No",IF(AND($G7>=EarlyDays,OR($J7="",TODAY()-$J7>=ReminderGapDays)),"Yes","No"))
A8: 46049 | B8: Adam R Abdallah | C8: 547743*3740 | E8: 0754562295 | G8: =IF($I8="",TODAY()-$A8,$I8-$A8) | H8: Issued | I8: 46051 | L8: =IF($G8>=DueDays,"Due",IF($G8>=WarnDays,"Warning",IF($G8>=EarlyDays,"Normal","New"))) | M8: =IFS($H8="Held","In Branch",$H8="Issued","Collected",$H8="Destroyed","Destroyed",TRUE,"Pending") | N8: =AND($H8="Held",$G8>=DueDays) | O8: =IF($N8,$G8-DueDays,"") | P8: =COUNTIF('Communication Log'!$C:$C,$C8) | Q8: =IF($H8<>"Held","No",IF(AND($G8>=EarlyDays,OR($J8="",TODAY()-$J8>=ReminderGapDays)),"Yes","No"))
A9: 46051 | B9: Elly Simiyu | C9: 547743*9942 | E9: 0715136561 | G9: =IF($I9="",TODAY()-$A9,$I9-$A9) | H9: Issued | I9: 46051 | L9: =IF($G9>=DueDays,"Due",IF($G9>=WarnDays,"Warning",IF($G9>=EarlyDays,"Normal","New"))) | M9: =IFS($H9="Held","In Branch",$H9="Issued","Collected",$H9="Destroyed","Destroyed",TRUE,"Pending") | N9: =AND($H9="Held",$G9>=DueDays) | O9: =IF($N9,$G9-DueDays,"") | P9: =COUNTIF('Communication Log'!$C:$C,$C9) | Q9: =IF($H9<>"Held","No",IF(AND($G9>=EarlyDays,OR($J9="",TODAY()-$J9>=ReminderGapDays)),"Yes","No"))
A10: 46053 | B10: Noreene Ngatu | C10: 417360*6836 | E10: 0710280135 | G10: =IF($I10="",TODAY()-$A10,$I10-$A10) | H10: Issued | I10: 46055 | L10: =IF($G10>=DueDays,"Due",IF($G10>=WarnDays,"Warning",IF($G10>=EarlyDays,"Normal","New"))) | M10: =IFS($H10="Held","In Branch",$H10="Issued","Collected",$H10="Destroyed","Destroyed",TRUE,"Pending") | N10: =AND($H10="Held",$G10>=DueDays) | O10: =IF($N10,$G10-DueDays,"") | P10: =COUNTIF('Communication Log'!$C:$C,$C10) | Q10: =IF($H10<>"Held","No",IF(AND($G10>=EarlyDays,OR($J10="",TODAY()-$J10>=ReminderGapDays)),"Yes","No"))
A11: 46056 | B11: Juliet Olwala | C11: 555458*9732 | E11: 0724716589 | G11: =IF($I11="",TODAY()-$A11,$I11-$A11) | H11: Issued | I11: 46057 | L11: =IF($G11>=DueDays,"Due",IF($G11>=WarnDays,"Warning",IF($G11>=EarlyDays,"Normal","New"))) | M11: =IFS($H11="Held","In Branch",$H11="Issued","Collected",$H11="Destroyed","Destroyed",TRUE,"Pending") | N11: =AND($H11="Held",$G11>=DueDays) | O11: =IF($N11,$G11-DueDays,"") | P11: =COUNTIF('Communication Log'!$C:$C,$C11) | Q11: =IF($H11<>"Held","No",IF(AND($G11>=EarlyDays,OR($J11="",TODAY()-$J11>=ReminderGapDays)),"Yes","No"))
A12: 46069 | B12: Mustafa Janoowala | C12: 547743*6179 | E12: 0757776125 | G12: =IF($I12="",TODAY()-$A12,$I12-$A12) | H12: Issued | I12: 46069 | L12: =IF($G12>=DueDays,"Due",IF($G12>=WarnDays,"Warning",IF($G12>=EarlyDays,"Normal","New"))) | M12: =IFS($H12="Held","In Branch",$H12="Issued","Collected",$H12="Destroyed","Destroyed",TRUE,"Pending") | N12: =AND($H12="Held",$G12>=DueDays) | O12: =IF($N12,$G12-DueDays,"") | P12: =COUNTIF('Communication Log'!$C:$C,$C12) | Q12: =IF($H12<>"Held","No",IF(AND($G12>=EarlyDays,OR($J12="",TODAY()-$J12>=ReminderGapDays)),"Yes","No"))
A13: 46055 | B13: Samuel Waweru | C13: 547743*5868 | E13: 0720742752 | G13: =IF($I13="",TODAY()-$A13,$I13-$A13) | H13: Issued | I13: 46071 | L13: =IF($G13>=DueDays,"Due",IF($G13>=WarnDays,"Warning",IF($G13>=EarlyDays,"Normal","New"))) | M13: =IFS($H13="Held","In Branch",$H13="Issued","Collected",$H13="Destroyed","Destroyed",TRUE,"Pending") | N13: =AND($H13="Held",$G13>=DueDays) | O13: =IF($N13,$G13-DueDays,"") | P13: =COUNTIF('Communication Log'!$C:$C,$C13) | Q13: =IF($H13<>"Held","No",IF(AND($G13>=EarlyDays,OR($J13="",TODAY()-$J13>=ReminderGapDays)),"Yes","No"))
A14: 46069 | B14: Nivendu Sennik | C14: 410486*7245 | E14: 0737511135 | G14: =IF($I14="",TODAY()-$A14,$I14-$A14) | H14: Issued | I14: 46077 | L14: =IF($G14>=DueDays,"Due",IF($G14>=WarnDays,"Warning",IF($G14>=EarlyDays,"Normal","New"))) | M14: =IFS($H14="Held","In Branch",$H14="Issued","Collected",$H14="Destroyed","Destroyed",TRUE,"Pending") | N14: =AND($H14="Held",$G14>=DueDays) | O14: =IF($N14,$G14-DueDays,"") | P14: =COUNTIF('Communication Log'!$C:$C,$C14) | Q14: =IF($H14<>"Held","No",IF(AND($G14>=EarlyDays,OR($J14="",TODAY()-$J14>=ReminderGapDays)),"Yes","No"))
A15: 46074 | B15: Gerald Otieno | C15: 547743*9968 | E15: 0715278204 | G15: =IF($I15="",TODAY()-$A15,$I15-$A15) | H15: Issued | I15: 46077 | L15: =IF($G15>=DueDays,"Due",IF($G15>=WarnDays,"Warning",IF($G15>=EarlyDays,"Normal","New"))) | M15: =IFS($H15="Held","In Branch",$H15="Issued","Collected",$H15="Destroyed","Destroyed",TRUE,"Pending") | N15: =AND($H15="Held",$G15>=DueDays) | O15: =IF($N15,$G15-DueDays,"") | P15: =COUNTIF('Communication Log'!$C:$C,$C15) | Q15: =IF($H15<>"Held","No",IF(AND($G15>=EarlyDays,OR($J15="",TODAY()-$J15>=ReminderGapDays)),"Yes","No"))
A16: 46065 | B16: Hamid Alvi | C16: 555458*0173 | E16: 0700126155 | G16: =IF($I16="",TODAY()-$A16,$I16-$A16) | H16: Issued | I16: 46078 | L16: =IF($G16>=DueDays,"Due",IF($G16>=WarnDays,"Warning",IF($G16>=EarlyDays,"Normal","New"))) | M16: =IFS($H16="Held","In Branch",$H16="Issued","Collected",$H16="Destroyed","Destroyed",TRUE,"Pending") | N16: =AND($H16="Held",$G16>=DueDays) | O16: =IF($N16,$G16-DueDays,"") | P16: =COUNTIF('Communication Log'!$C:$C,$C16) | Q16: =IF($H16<>"Held","No",IF(AND($G16>=EarlyDays,OR($J16="",TODAY()-$J16>=ReminderGapDays)),"Yes","No"))
A17: 46065 | B17: Sobia Sardar | C17: 555458*1546 | E17: N/A | G17: =IF($I17="",TODAY()-$A17,$I17-$A17) | H17: Issued | I17: 46078 | L17: =IF($G17>=DueDays,"Due",IF($G17>=WarnDays,"Warning",IF($G17>=EarlyDays,"Normal","New"))) | M17: =IFS($H17="Held","In Branch",$H17="Issued","Collected",$H17="Destroyed","Destroyed",TRUE,"Pending") | N17: =AND($H17="Held",$G17>=DueDays) | O17: =IF($N17,$G17-DueDays,"") | P17: =COUNTIF('Communication Log'!$C:$C,$C17) | Q17: =IF($H17<>"Held","No",IF(AND($G17>=EarlyDays,OR($J17="",TODAY()-$J17>=ReminderGapDays)),"Yes","No"))
A18: 46077 | B18: Rajkumar Patil | C18: 555458*1873 | E18: 0735500050 | G18: =IF($I18="",TODAY()-$A18,$I18-$A18) | H18: Issued | I18: 46078 | L18: =IF($G18>=DueDays,"Due",IF($G18>=WarnDays,"Warning",IF($G18>=EarlyDays,"Normal","New"))) | M18: =IFS($H18="Held","In Branch",$H18="Issued","Collected",$H18="Destroyed","Destroyed",TRUE,"Pending") | N18: =AND($H18="Held",$G18>=DueDays) | O18: =IF($N18,$G18-DueDays,"") | P18: =COUNTIF('Communication Log'!$C:$C,$C18) | Q18: =IF($H18<>"Held","No",IF(AND($G18>=EarlyDays,OR($J18="",TODAY()-$J18>=ReminderGapDays)),"Yes","No"))
A19: 46076 | B19: Michael Mburu | C19: 547743*9243 | E19: 0726250213 | G19: =IF($I19="",TODAY()-$A19,$I19-$A19) | H19: Issued | I19: 46079 | L19: =IF($G19>=DueDays,"Due",IF($G19>=WarnDays,"Warning",IF($G19>=EarlyDays,"Normal","New"))) | M19: =IFS($H19="Held","In Branch",$H19="Issued","Collected",$H19="Destroyed","Destroyed",TRUE,"Pending") | N19: =AND($H19="Held",$G19>=DueDays) | O19: =IF($N19,$G19-DueDays,"") | P19: =COUNTIF('Communication Log'!$C:$C,$C19) | Q19: =IF($H19<>"Held","No",IF(AND($G19>=EarlyDays,OR($J19="",TODAY()-$J19>=ReminderGapDays)),"Yes","No"))
A20: 46069 | B20: Levis Mungai | C20: 547743*8499 | E20: 0743269225 | F20: nyoikslevis@gmail.com | G20: =IF($I20="",TODAY()-$A20,$I20-$A20) | H20: Issued | I20: 46083 | L20: =IF($G20>=DueDays,"Due",IF($G20>=WarnDays,"Warning",IF($G20>=EarlyDays,"Normal","New"))) | M20: =IFS($H20="Held","In Branch",$H20="Issued","Collected",$H20="Destroyed","Destroyed",TRUE,"Pending") | N20: =AND($H20="Held",$G20>=DueDays) | O20: =IF($N20,$G20-DueDays,"") | P20: =COUNTIF('Communication Log'!$C:$C,$C20) | Q20: =IF($H20<>"Held","No",IF(AND($G20>=EarlyDays,OR($J20="",TODAY()-$J20>=ReminderGapDays)),"Yes","No"))
A21: 46052 | B21: Richard O Oluoch | C21: 547743*1774 | E21: 0715971967 | G21: =IF($I21="",TODAY()-$A21,$I21-$A21) | H21: Issued | I21: 46087 | L21: =IF($G21>=DueDays,"Due",IF($G21>=WarnDays,"Warning",IF($G21>=EarlyDays,"Normal","New"))) | M21: =IFS($H21="Held","In Branch",$H21="Issued","Collected",$H21="Destroyed","Destroyed",TRUE,"Pending") | N21: =AND($H21="Held",$G21>=DueDays) | O21: =IF($N21,$G21-DueDays,"") | P21: =COUNTIF('Communication Log'!$C:$C,$C21) | Q21: =IF($H21<>"Held","No",IF(AND($G21>=EarlyDays,OR($J21="",TODAY()-$J21>=ReminderGapDays)),"Yes","No"))
A22: 46060 | B22: Jeremiah Rashuta | C22: 547743*7312 | E22: 0700466345 | F22: jerezykeysere@gmail.com | G22: =IF($I22="",TODAY()-$A22,$I22-$A22) | H22: Issued | I22: 46104 | K22: Nyahururu | L22: =IF($G22>=DueDays,"Due",IF($G22>=WarnDays,"Warning",IF($G22>=EarlyDays,"Normal","New"))) | M22: =IFS($H22="Held","In Branch",$H22="Issued","Collected",$H22="Destroyed","Destroyed",TRUE,"Pending") | N22: =AND($H22="Held",$G22>=DueDays) | O22: =IF($N22,$G22-DueDays,"") | P22: =COUNTIF('Communication Log'!$C:$C,$C22) | Q22: =IF($H22<>"Held","No",IF(AND($G22>=EarlyDays,OR($J22="",TODAY()-$J22>=ReminderGapDays)),"Yes","No"))
A23: 46063 | B23: Teresia Chege | C23: 547743*8641 | E23: 0713433957 | G23: =IF($I23="",TODAY()-$A23,$I23-$A23) | H23: Destroyed | K23: Cancelled | L23: =IF($G23>=DueDays,"Due",IF($G23>=WarnDays,"Warning",IF($G23>=EarlyDays,"Normal","New"))) | M23: =IFS($H23="Held","In Branch",$H23="Issued","Collected",$H23="Destroyed","Destroyed",TRUE,"Pending") | N23: =AND($H23="Held",$G23>=DueDays) | O23: =IF($N23,$G23-DueDays,"") | P23: =COUNTIF('Communication Log'!$C:$C,$C23) | Q23: =IF($H23<>"Held","No",IF(AND($G23>=EarlyDays,OR($J23="",TODAY()-$J23>=ReminderGapDays)),"Yes","No"))
A24: 46063 | B24: Winie Ouma | C24: 547743*2414 | E24: 0723310720 | G24: =IF($I24="",TODAY()-$A24,$I24-$A24) | H24: Issued | I24: 46104 | K24: Baba Dogo | L24: =IF($G24>=DueDays,"Due",IF($G24>=WarnDays,"Warning",IF($G24>=EarlyDays,"Normal","New"))) | M24: =IFS($H24="Held","In Branch",$H24="Issued","Collected",$H24="Destroyed","Destroyed",TRUE,"Pending") | N24: =AND($H24="Held",$G24>=DueDays) | O24: =IF($N24,$G24-DueDays,"") | P24: =COUNTIF('Communication Log'!$C:$C,$C24) | Q24: =IF($H24<>"Held","No",IF(AND($G24>=EarlyDays,OR($J24="",TODAY()-$J24>=ReminderGapDays)),"Yes","No"))
A25: 46080 | B25: Alexander Kinyua | C25: 547743*6403 | E25: 0711891983 | G25: =IF($I25="",TODAY()-$A25,$I25-$A25) | H25: Issued | I25: 46087 | L25: =IF($G25>=DueDays,"Due",IF($G25>=WarnDays,"Warning",IF($G25>=EarlyDays,"Normal","New"))) | M25: =IFS($H25="Held","In Branch",$H25="Issued","Collected",$H25="Destroyed","Destroyed",TRUE,"Pending") | N25: =AND($H25="Held",$G25>=DueDays) | O25: =IF($N25,$G25-DueDays,"") | P25: =COUNTIF('Communication Log'!$C:$C,$C25) | Q25: =IF($H25<>"Held","No",IF(AND($G25>=EarlyDays,OR($J25="",TODAY()-$J25>=ReminderGapDays)),"Yes","No"))
A26: 46069 | B26: Erick Njoki | C26: 547743*0560 | E26: 0707241732 | F26: ericknjoki004@gmail.com | G26: =IF($I26="",TODAY()-$A26,$I26-$A26) | H26: Issued | I26: 46104 | K26: Kitengela | L26: =IF($G26>=DueDays,"Due",IF($G26>=WarnDays,"Warning",IF($G26>=EarlyDays,"Normal","New"))) | M26: =IFS($H26="Held","In Branch",$H26="Issued","Collected",$H26="Destroyed","Destroyed",TRUE,"Pending") | N26: =AND($H26="Held",$G26>=DueDays) | O26: =IF($N26,$G26-DueDays,"") | P26: =COUNTIF('Communication Log'!$C:$C,$C26) | Q26: =IF($H26<>"Held","No",IF(AND($G26>=EarlyDays,OR($J26="",TODAY()-$J26>=ReminderGapDays)),"Yes","No"))
A27: 46088 | B27: Bubby Afande | C27: 547743*8032 | E27: 0701512441 | G27: =IF($I27="",TODAY()-$A27,$I27-$A27) | H27: Issued | I27: 46088 | L27: =IF($G27>=DueDays,"Due",IF($G27>=WarnDays,"Warning",IF($G27>=EarlyDays,"Normal","New"))) | M27: =IFS($H27="Held","In Branch",$H27="Issued","Collected",$H27="Destroyed","Destroyed",TRUE,"Pending") | N27: =AND($H27="Held",$G27>=DueDays) | O27: =IF($N27,$G27-DueDays,"") | P27: =COUNTIF('Communication Log'!$C:$C,$C27) | Q27: =IF($H27<>"Held","No",IF(AND($G27>=EarlyDays,OR($J27="",TODAY()-$J27>=ReminderGapDays)),"Yes","No"))
A28: 46079 | B28: David Mwangi | C28: 547743*7689 | E28: 0791629373 | G28: =IF($I28="",TODAY()-$A28,$I28-$A28) | H28: Issued | I28: 46090 | L28: =IF($G28>=DueDays,"Due",IF($G28>=WarnDays,"Warning",IF($G28>=EarlyDays,"Normal","New"))) | M28: =IFS($H28="Held","In Branch",$H28="Issued","Collected",$H28="Destroyed","Destroyed",TRUE,"Pending") | N28: =AND($H28="Held",$G28>=DueDays) | O28: =IF($N28,$G28-DueDays,"") | P28: =COUNTIF('Communication Log'!$C:$C,$C28) | Q28: =IF($H28<>"Held","No",IF(AND($G28>=EarlyDays,OR($J28="",TODAY()-$J28>=ReminderGapDays)),"Yes","No"))
A29: 46065 | B29: Xuehua Tan | C29: 555458*3724 | E29: 07113667 | G29: =IF($I29="",TODAY()-$A29,$I29-$A29) | H29: Issued | I29: 46091 | L29: =IF($G29>=DueDays,"Due",IF($G29>=WarnDays,"Warning",IF($G29>=EarlyDays,"Normal","New"))) | M29: =IFS($H29="Held","In Branch",$H29="Issued","Collected",$H29="Destroyed","Destroyed",TRUE,"Pending") | N29: =AND($H29="Held",$G29>=DueDays) | O29: =IF($N29,$G29-DueDays,"") | P29: =COUNTIF('Communication Log'!$C:$C,$C29) | Q29: =IF($H29<>"Held","No",IF(AND($G29>=EarlyDays,OR($J29="",TODAY()-$J29>=ReminderGapDays)),"Yes","No"))
A30: 46088 | B30: Amardeep Satinder | C30: 555458*7346 | E30: 0734511100 | G30: =IF($I30="",TODAY()-$A30,$I30-$A30) | H30: Issued | I30: 46094 | L30: =IF($G30>=DueDays,"Due",IF($G30>=WarnDays,"Warning",IF($G30>=EarlyDays,"Normal","New"))) | M30: =IFS($H30="Held","In Branch",$H30="Issued","Collected",$H30="Destroyed","Destroyed",TRUE,"Pending") | N30: =AND($H30="Held",$G30>=DueDays) | O30: =IF($N30,$G30-DueDays,"") | P30: =COUNTIF('Communication Log'!$C:$C,$C30) | Q30: =IF($H30<>"Held","No",IF(AND($G30>=EarlyDays,OR($J30="",TODAY()-$J30>=ReminderGapDays)),"Yes","No"))
A31: 46088 | B31: Hafsa Abdikeir | C31: 527775*3561 | E31: 0722732149 | G31: =IF($I31="",TODAY()-$A31,$I31-$A31) | H31: Issued | I31: 46094 | L31: =IF($G31>=DueDays,"Due",IF($G31>=WarnDays,"Warning",IF($G31>=EarlyDays,"Normal","New"))) | M31: =IFS($H31="Held","In Branch",$H31="Issued","Collected",$H31="Destroyed","Destroyed",TRUE,"Pending") | N31: =AND($H31="Held",$G31>=DueDays) | O31: =IF($N31,$G31-DueDays,"") | P31: =COUNTIF('Communication Log'!$C:$C,$C31) | Q31: =IF($H31<>"Held","No",IF(AND($G31>=EarlyDays,OR($J31="",TODAY()-$J31>=ReminderGapDays)),"Yes","No"))
A32: 46088 | B32: Meimuna Abdikeir | C32: 527775*7128 | E32: 0722504637 | G32: =IF($I32="",TODAY()-$A32,$I32-$A32) | H32: Issued | I32: 46094 | L32: =IF($G32>=DueDays,"Due",IF($G32>=WarnDays,"Warning",IF($G32>=EarlyDays,"Normal","New"))) | M32: =IFS($H32="Held","In Branch",$H32="Issued","Collected",$H32="Destroyed","Destroyed",TRUE,"Pending") | N32: =AND($H32="Held",$G32>=DueDays) | O32: =IF($N32,$G32-DueDays,"") | P32: =COUNTIF('Communication Log'!$C:$C,$C32) | Q32: =IF($H32<>"Held","No",IF(AND($G32>=EarlyDays,OR($J32="",TODAY()-$J32>=ReminderGapDays)),"Yes","No"))
A33: 46077 | B33: Michael Obatt | C33: 547743*7683 | E33: 0708088389 | F33: michaeljairo33@gmail.com | G33: =IF($I33="",TODAY()-$A33,$I33-$A33) | H33: Pend | L33: =IF($G33>=DueDays,"Due",IF($G33>=WarnDays,"Warning",IF($G33>=EarlyDays,"Normal","New"))) | M33: =IFS($H33="Held","In Branch",$H33="Issued","Collected",$H33="Destroyed","Destroyed",TRUE,"Pending") | N33: =AND($H33="Held",$G33>=DueDays) | O33: =IF($N33,$G33-DueDays,"") | P33: =COUNTIF('Communication Log'!$C:$C,$C33) | Q33: =IF($H33<>"Held","No",IF(AND($G33>=EarlyDays,OR($J33="",TODAY()-$J33>=ReminderGapDays)),"Yes","No"))
A34: 46050 | B34: Jallen Dola | C34: 547743*6107 | E34: 0720845628 | F34: jadencoenterprises@gmail.com | G34: =IF($I34="",TODAY()-$A34,$I34-$A34) | H34: Issued | I34: 46097 | L34: =IF($G34>=DueDays,"Due",IF($G34>=WarnDays,"Warning",IF($G34>=EarlyDays,"Normal","New"))) | M34: =IFS($H34="Held","In Branch",$H34="Issued","Collected",$H34="Destroyed","Destroyed",TRUE,"Pending") | N34: =AND($H34="Held",$G34>=DueDays) | O34: =IF($N34,$G34-DueDays,"") | P34: =COUNTIF('Communication Log'!$C:$C,$C34) | Q34: =IF($H34<>"Held","No",IF(AND($G34>=EarlyDays,OR($J34="",TODAY()-$J34>=ReminderGapDays)),"Yes","No"))
A35: 46079 | B35: Asamuel Motuku | C35: 547743*0029 | E35: 0724010183 | F35: mutukusamuel556@gmail.com | G35: =IF($I35="",TODAY()-$A35,$I35-$A35) | H35: Destroyed | K35: To destroy, incorrect name | L35: =IF($G35>=DueDays,"Due",IF($G35>=WarnDays,"Warning",IF($G35>=EarlyDays,"Normal","New"))) | M35: =IFS($H35="Held","In Branch",$H35="Issued","Collected",$H35="Destroyed","Destroyed",TRUE,"Pending") | N35: =AND($H35="Held",$G35>=DueDays) | O35: =IF($N35,$G35-DueDays,"") | P35: =COUNTIF('Communication Log'!$C:$C,$C35) | Q35: =IF($H35<>"Held","No",IF(AND($G35>=EarlyDays,OR($J35="",TODAY()-$J35>=ReminderGapDays)),"Yes","No"))
A36: 46098 | B36: Salima A Tejani | C36: 558252*5770 | E36: 0733786161 | G36: =IF($I36="",TODAY()-$A36,$I36-$A36) | H36: Issued | I36: 46098 | L36: =IF($G36>=DueDays,"Due",IF($G36>=WarnDays,"Warning",IF($G36>=EarlyDays,"Normal","New"))) | M36: =IFS($H36="Held","In Branch",$H36="Issued","Collected",$H36="Destroyed","Destroyed",TRUE,"Pending") | N36: =AND($H36="Held",$G36>=DueDays) | O36: =IF($N36,$G36-DueDays,"") | P36: =COUNTIF('Communication Log'!$C:$C,$C36) | Q36: =IF($H36<>"Held","No",IF(AND($G36>=EarlyDays,OR($J36="",TODAY()-$J36>=ReminderGapDays)),"Yes","No"))
A37: 46097 | B37: Nicholas Mutinda Kitu | C37: 547743*2133 | E37: 0700402682 | G37: =IF($I37="",TODAY()-$A37,$I37-$A37) | H37: Issued | I37: 46098 | L37: =IF($G37>=DueDays,"Due",IF($G37>=WarnDays,"Warning",IF($G37>=EarlyDays,"Normal","New"))) | M37: =IFS($H37="Held","In Branch",$H37="Issued","Collected",$H37="Destroyed","Destroyed",TRUE,"Pending") | N37: =AND($H37="Held",$G37>=DueDays) | O37: =IF($N37,$G37-DueDays,"") | P37: =COUNTIF('Communication Log'!$C:$C,$C37) | Q37: =IF($H37<>"Held","No",IF(AND($G37>=EarlyDays,OR($J37="",TODAY()-$J37>=ReminderGapDays)),"Yes","No"))
A38: 46088 | B38: Ann Wanjiku Thuo | C38: 547743*0324 | E38: 0704626352 | G38: =IF($I38="",TODAY()-$A38,$I38-$A38) | H38: Issued | I38: 46104 | K38: Kawangware | L38: =IF($G38>=DueDays,"Due",IF($G38>=WarnDays,"Warning",IF($G38>=EarlyDays,"Normal","New"))) | M38: =IFS($H38="Held","In Branch",$H38="Issued","Collected",$H38="Destroyed","Destroyed",TRUE,"Pending") | N38: =AND($H38="Held",$G38>=DueDays) | O38: =IF($N38,$G38-DueDays,"") | P38: =COUNTIF('Communication Log'!$C:$C,$C38) | Q38: =IF($H38<>"Held","No",IF(AND($G38>=EarlyDays,OR($J38="",TODAY()-$J38>=ReminderGapDays)),"Yes","No"))
A39: 46091 | B39: Ken Kaboori | C39: 547743*7308 | E39: 0726417285 | F39: kenbundikaboori@gmail.com | G39: =IF($I39="",TODAY()-$A39,$I39-$A39) | H39: Issued | I39: 46099 | J39: 46099.711 | L39: =IF($G39>=DueDays,"Due",IF($G39>=WarnDays,"Warning",IF($G39>=EarlyDays,"Normal","New"))) | M39: =IFS($H39="Held","In Branch",$H39="Issued","Collected",$H39="Destroyed","Destroyed",TRUE,"Pending") | N39: =AND($H39="Held",$G39>=DueDays) | O39: =IF($N39,$G39-DueDays,"") | P39: =COUNTIF('Communication Log'!$C:$C,$C39) | Q39: =IF($H39<>"Held","No",IF(AND($G39>=EarlyDays,OR($J39="",TODAY()-$J39>=ReminderGapDays)),"Yes","No"))
A40: 46091 | B40: Chintan Gohel | C40: 547743*2688 | E40: 0713662894 | F40: chintangohel@live.com | G40: =IF($I40="",TODAY()-$A40,$I40-$A40) | H40: Issued | I40: 46113 | J40: 46099.711 | K40: G.Way | L40: =IF($G40>=DueDays,"Due",IF($G40>=WarnDays,"Warning",IF($G40>=EarlyDays,"Normal","New"))) | M40: =IFS($H40="Held","In Branch",$H40="Issued","Collected",$H40="Destroyed","Destroyed",TRUE,"Pending") | N40: =AND($H40="Held",$G40>=DueDays) | O40: =IF($N40,$G40-DueDays,"") | P40: =COUNTIF('Communication Log'!$C:$C,$C40) | Q40: =IF($H40<>"Held","No",IF(AND($G40>=EarlyDays,OR($J40="",TODAY()-$J40>=ReminderGapDays)),"Yes","No"))
...

Sheet Communication Log
A1: Date Sent | B1: Customer Name | C1: Card Number | D1: Email Address | E1: Email | F1: Type | G1: Sent by

Sheet Reminder Log
A1: Date Sent | B1: Customer Name | C1: Email Address | D1: Card Number | E1: TIB | F1: Status | G1: Email Subject

Sheet _calc
A1: Status | B1: Cards | D1: Age Band | E1: Cards | G1: Month | H1: Cards Recorded | J1: seg | K1: New | L1: Normal | M1: Warning | N1: Due
A2: In Branch (Held) | B2: =COUNTIF('Card Register'!$H$2:$H$50,"Held*") | D2: New (0-29) | E2: =COUNTIFS('Card Register'!$G$2:$G$50,">=0",'Card Register'!$G$2:$G$50,"<"&EarlyDays) | G2: 46023 | H2: =COUNTIFS('Card Register'!$A$2:$A$50,">="&DATE(2026,1,1),'Card Register'!$A$2:$A$50,"<"&DATE(2026,2,1)) | J2: Portfolio | K2: =_calc!$E$2 | L2: =_calc!$E$3 | M2: =_calc!$E$4 | N2: =_calc!$E$5
A3: Collected (Issued) | B3: =COUNTIF('Card Register'!$H$2:$H$50,"Issued*") | D3: Normal (30-59) | E3: =COUNTIFS('Card Register'!$G$2:$G$50,">="&EarlyDays,'Card Register'!$G$2:$G$50,"<"&WarnDays) | G3: 46054 | H3: =COUNTIFS('Card Register'!$A$2:$A$50,">="&DATE(2026,2,1),'Card Register'!$A$2:$A$50,"<"&DATE(2026,3,1))
A4: Destroyed | B4: =COUNTIF('Card Register'!$H$2:$H$50,"Destroyed*") | D4: Warning (60-89) | E4: =COUNTIFS('Card Register'!$G$2:$G$50,">="&WarnDays,'Card Register'!$G$2:$G$50,"<"&DueDays) | G4: 46082 | H4: =COUNTIFS('Card Register'!$A$2:$A$50,">="&DATE(2026,3,1),'Card Register'!$A$2:$A$50,"<"&DATE(2026,4,1))
A5: Pending | B5: =COUNTIF('Card Register'!$H$2:$H$50,"Pend*") | D5: Due 90+ | E5: =COUNTIFS('Card Register'!$G$2:$G$50,">="&DueDays) | G5: 46113 | H5: =COUNTIFS('Card Register'!$A$2:$A$50,">="&DATE(2026,4,1),'Card Register'!$A$2:$A$50,"<"&DATE(2026,5,1))
G6: 46143 | H6: =COUNTIFS('Card Register'!$A$2:$A$50,">="&DATE(2026,5,1),'Card Register'!$A$2:$A$50,"<"&DATE(2026,6,1))
G7: 46174 | H7: =COUNTIFS('Card Register'!$A$2:$A$50,">="&DATE(2026,6,1),'Card Register'!$A$2:$A$50,"<"&DATE(2026,7,1))
G8: 46204 | H8: =COUNTIFS('Card Register'!$A$2:$A$50,">="&DATE(2026,7,1),'Card Register'!$A$2:$A$50,"<"&DATE(2026,8,1))
G9: 46235 | H9: =COUNTIFS('Card Register'!$A$2:$A$50,">="&DATE(2026,8,1),'Card Register'!$A$2:$A$50,"<"&DATE(2026,9,1))
G10: 46266 | H10: =COUNTIFS('Card Register'!$A$2:$A$50,">="&DATE(2026,9,1),'Card Register'!$A$2:$A$50,"<"&DATE(2026,10,1))
G11: 46296 | H11: =COUNTIFS('Card Register'!$A$2:$A$50,">="&DATE(2026,10,1),'Card Register'!$A$2:$A$50,"<"&DATE(2026,11,1))
G12: 46327 | H12: =COUNTIFS('Card Register'!$A$2:$A$50,">="&DATE(2026,11,1),'Card Register'!$A$2:$A$50,"<"&DATE(2026,12,1))
G13: 46357 | H13: =COUNTIFS('Card Register'!$A$2:$A$50,">="&DATE(2026,12,1),'Card Register'!$A$2:$A$50,"<"&DATE(2027,1,1))
